12:13:36, 380 BOT_LOGGER INFO: Trying to connect to the linking server...
12:13:37, 404 BOT_LOGGER INFO: Can't connect to the linking server... New connection try after 2 seconds...
12:13:40, 423 BOT_LOGGER INFO: Can't connect to the linking server... New connection try after 2 seconds...
12:13:43, 455 BOT_LOGGER INFO: Can't connect to the linking server... New connection try after 2 seconds...
12:13:46, 480 BOT_LOGGER INFO: Can't connect to the linking server... New connection try after 2 seconds...
12:13:49, 518 BOT_LOGGER INFO: Can't connect to the linking server... New connection try after 2 seconds...
12:13:52, 544 BOT_LOGGER INFO: Can't connect to the linking server... New connection try after 2 seconds...
12:13:55, 561 BOT_LOGGER INFO: Can't connect to the linking server... New connection try after 2 seconds...
12:13:58, 590 BOT_LOGGER INFO: Can't connect to the linking server... New connection try after 2 seconds...
12:14:01, 607 BOT_LOGGER INFO: Can't connect to the linking server... New connection try after 2 seconds...
12:14:04, 628 BOT_LOGGER INFO: Can't connect to the linking server... New connection try after 2 seconds...
12:14:07, 648 BOT_LOGGER INFO: Can't connect to the linking server... New connection try after 2 seconds...
12:14:10, 679 BOT_LOGGER INFO: Can't connect to the linking server... New connection try after 2 seconds...
12:14:13, 705 BOT_LOGGER INFO: Can't connect to the linking server... New connection try after 2 seconds...
12:14:16, 727 BOT_LOGGER INFO: Can't connect to the linking server... New connection try after 2 seconds...
12:14:19, 751 BOT_LOGGER INFO: Can't connect to the linking server... New connection try after 2 seconds...
12:14:22, 776 BOT_LOGGER INFO: Can't connect to the linking server... New connection try after 2 seconds...
12:14:25, 806 BOT_LOGGER INFO: Can't connect to the linking server... New connection try after 2 seconds...
12:14:28, 828 BOT_LOGGER INFO: Can't connect to the linking server... New connection try after 2 seconds...
12:14:31, 866 BOT_LOGGER INFO: Can't connect to the linking server... New connection try after 2 seconds...
12:24:16, 53 BOT_LOGGER INFO: Trying to connect to the linking server...
12:30:52, 996 BOT_LOGGER INFO: Trying to connect to the linking server...
12:31:37, 303 BOT_LOGGER INFO: Trying to connect to the linking server...
12:31:38, 329 BOT_LOGGER INFO: Can't connect to the linking server... New connection try after 2 seconds...
12:31:41, 358 BOT_LOGGER INFO: Can't connect to the linking server... New connection try after 2 seconds...
12:32:22, 236 BOT_LOGGER INFO: Trying to connect to the linking server...
12:33:01, 886 BOT_LOGGER INFO: Trying to connect to the linking server...
12:33:02, 900 BOT_LOGGER INFO: Linking server doesn't responsing...
12:33:02, 901 BOT_LOGGER INFO: Can't connect to the linking server... New connection try after 2 seconds...
12:33:05, 935 BOT_LOGGER INFO: Linking server doesn't responsing...
12:33:05, 936 BOT_LOGGER INFO: Can't connect to the linking server... New connection try after 2 seconds...
12:33:08, 968 BOT_LOGGER INFO: Linking server doesn't responsing...
12:33:08, 969 BOT_LOGGER INFO: Can't connect to the linking server... New connection try after 2 seconds...
12:33:11, 999 BOT_LOGGER INFO: Linking server doesn't responsing...
12:33:12, 0 BOT_LOGGER INFO: Can't connect to the linking server... New connection try after 2 seconds...
12:33:15, 19 BOT_LOGGER INFO: Linking server doesn't responsing...
12:33:15, 20 BOT_LOGGER INFO: Can't connect to the linking server... New connection try after 2 seconds...
12:33:18, 43 BOT_LOGGER INFO: Linking server doesn't responsing...
12:33:18, 44 BOT_LOGGER INFO: Can't connect to the linking server... New connection try after 2 seconds...
12:33:21, 71 BOT_LOGGER INFO: Linking server doesn't responsing...
12:33:21, 72 BOT_LOGGER INFO: Can't connect to the linking server... New connection try after 2 seconds...
12:33:24, 106 BOT_LOGGER INFO: Linking server doesn't responsing...
12:33:24, 107 BOT_LOGGER INFO: Can't connect to the linking server... New connection try after 2 seconds...
12:33:27, 131 BOT_LOGGER INFO: Linking server doesn't responsing...
12:33:27, 132 BOT_LOGGER INFO: Can't connect to the linking server... New connection try after 2 seconds...
12:35:10, 294 BOT_LOGGER INFO: Trying to connect to the linking server...
12:35:11, 321 BOT_LOGGER INFO: Linking server doesn't responsing... timed out
12:35:11, 322 BOT_LOGGER INFO: New request will execute in 2 seconds...
12:35:14, 346 BOT_LOGGER INFO: Linking server doesn't responsing... timed out
12:35:14, 347 BOT_LOGGER INFO: New request will execute in 2 seconds...
12:35:17, 357 BOT_LOGGER INFO: Linking server doesn't responsing... timed out
12:35:17, 358 BOT_LOGGER INFO: New request will execute in 2 seconds...
12:35:20, 394 BOT_LOGGER INFO: Linking server doesn't responsing... timed out
12:35:20, 395 BOT_LOGGER INFO: New request will execute in 2 seconds...
12:35:33, 520 BOT_LOGGER INFO: Trying to connect to the linking server...
12:35:34, 541 BOT_LOGGER INFO: Linking server doesn't responsing... Part of exception: timed out
12:35:34, 542 BOT_LOGGER INFO: New request will execute in 2 seconds...
12:35:37, 564 BOT_LOGGER INFO: Linking server doesn't responsing... Part of exception: timed out
12:35:37, 565 BOT_LOGGER INFO: New request will execute in 2 seconds...
12:42:24, 272 BOT_LOGGER INFO: Trying to connect to the linking server...
12:42:25, 292 BOT_LOGGER INFO: Linking server doesn't responsing... Part of exception: timed out
12:42:25, 293 BOT_LOGGER INFO: New request will execute in 2 seconds...
12:43:47, 532 BOT_LOGGER INFO: Trying to connect to the linking server...
12:44:04, 401 BOT_LOGGER INFO: Trying to connect to the linking server...
12:44:05, 415 BOT_LOGGER INFO: Linking server doesn't responsing... Part of exception: timed out
12:44:05, 416 BOT_LOGGER INFO: New request will execute in 2 seconds...
13:01:20, 773 BOT_LOGGER INFO: Trying to connect to the linking server...
13:01:20, 799 httpx._client DEBUG: HTTP Request: GET http://127.0.0.1:4000/status/server_status "HTTP/1.1 200 OK"
13:01:20, 800 BOT_LOGGER INFO: Connected !!!. Starting to data init
13:01:20, 814 httpx._client DEBUG: HTTP Request: GET http://127.0.0.1:4000/data/available_statuses "HTTP/1.1 200 OK"
13:01:20, 825 httpx._client DEBUG: HTTP Request: GET http://127.0.0.1:4000/data/beasts_statuses "HTTP/1.1 200 OK"
13:01:20, 839 httpx._client DEBUG: HTTP Request: GET http://127.0.0.1:4000/data/extended_mode_status "HTTP/1.1 200 OK"
13:01:33, 37 BOT_LOGGER INFO: Trying to connect to the linking server...
13:01:33, 52 httpx._client DEBUG: HTTP Request: GET http://127.0.0.1:4000/status/server_status "HTTP/1.1 200 OK"
13:01:33, 53 BOT_LOGGER INFO: Connected !!!. Starting to data init
13:01:33, 64 httpx._client DEBUG: HTTP Request: GET http://127.0.0.1:4000/data/available_statuses "HTTP/1.1 200 OK"
13:01:33, 91 httpx._client DEBUG: HTTP Request: GET http://127.0.0.1:4000/data/beasts_statuses "HTTP/1.1 200 OK"
13:01:33, 106 httpx._client DEBUG: HTTP Request: GET http://127.0.0.1:4000/data/extended_mode_status "HTTP/1.1 200 OK"
13:01:33, 365 BOT_LOGGER DEBUG: "BeastsFindingAction": STASH DATA WAS INITED
13:01:33, 365 BOT_LOGGER DEBUG: "BeastsFindingAction": SCREEN SCANNERS WAS INITED
13:01:33, 365 BOT_LOGGER DEBUG: "BeastsFindingAction": CONTROLLERS WAS INITED
13:01:33, 366 BOT_LOGGER DEBUG: "BeastsFindingAction": CONNECTORS WAS INITED
13:01:33, 378 httpx._client DEBUG: HTTP Request: POST http://127.0.0.1:4000/control/register_machine?vm_name=v3.18&port=4001&as_party_machine=true "HTTP/1.1 200 OK"
13:01:33, 379 BOT_LOGGER INFO: Data inited and bot is on pause...
13:01:33, 390 asyncio DEBUG: Using proactor: IocpProactor
13:01:33, 425 uvicorn.error INFO: Started server process [1384]
13:01:33, 425 uvicorn.error INFO: Waiting for application startup.
13:01:33, 426 uvicorn.error INFO: Application startup complete.
13:01:33, 427 uvicorn.error INFO: Uvicorn running on http://0.0.0.0:4001 (Press CTRL+C to quit)
13:02:26, 228 BOT_LOGGER CRITICAL: 
Traceback (most recent call last):
  File "d:\pprojects\poe_beast_bot_v3\beast_bot\run.py", line 39, in <module>
    BOT_INSTANCE.run()
  File "d:\pprojects\poe_beast_bot_v3\beast_bot\bot\bot_components\bot.py", line 163, in run
    self._sleep_controller.loop()
  File "d:\pprojects\poe_beast_bot_v3\beast_bot\bot\bot_components\general\sleep_controller\controller.py", line 49, in loop
    time.sleep(0.1)
KeyboardInterrupt
13:02:27, 248 REQUESTS_LOGGER WARNING: timed out... URL: http://127.0.0.1:4000/control/update_machine_status
Traceback (most recent call last):
  File "C:\Users\namst\AppData\Local\Programs\Python\Python310\lib\site-packages\httpcore\_exceptions.py", line 8, in map_exceptions
    yield
  File "C:\Users\namst\AppData\Local\Programs\Python\Python310\lib\site-packages\httpcore\backends\sync.py", line 86, in connect_tcp
    sock = socket.create_connection(
  File "C:\Users\namst\AppData\Local\Programs\Python\Python310\lib\socket.py", line 845, in create_connection
    raise err
  File "C:\Users\namst\AppData\Local\Programs\Python\Python310\lib\socket.py", line 833, in create_connection
    sock.connect(sa)
TimeoutError: timed out

During handling of the above exception, another exception occurred:

Traceback (most recent call last):
  File "C:\Users\namst\AppData\Local\Programs\Python\Python310\lib\site-packages\httpx\_transports\default.py", line 60, in map_httpcore_exceptions
    yield
  File "C:\Users\namst\AppData\Local\Programs\Python\Python310\lib\site-packages\httpx\_transports\default.py", line 218, in handle_request
    resp = self._pool.handle_request(req)
  File "C:\Users\namst\AppData\Local\Programs\Python\Python310\lib\site-packages\httpcore\_sync\connection_pool.py", line 253, in handle_request
    raise exc
  File "C:\Users\namst\AppData\Local\Programs\Python\Python310\lib\site-packages\httpcore\_sync\connection_pool.py", line 237, in handle_request
    response = connection.handle_request(request)
  File "C:\Users\namst\AppData\Local\Programs\Python\Python310\lib\site-packages\httpcore\_sync\connection.py", line 86, in handle_request
    raise exc
  File "C:\Users\namst\AppData\Local\Programs\Python\Python310\lib\site-packages\httpcore\_sync\connection.py", line 63, in handle_request
    stream = self._connect(request)
  File "C:\Users\namst\AppData\Local\Programs\Python\Python310\lib\site-packages\httpcore\_sync\connection.py", line 111, in _connect
    stream = self._network_backend.connect_tcp(**kwargs)
  File "C:\Users\namst\AppData\Local\Programs\Python\Python310\lib\site-packages\httpcore\backends\sync.py", line 85, in connect_tcp
    with map_exceptions(exc_map):
  File "C:\Users\namst\AppData\Local\Programs\Python\Python310\lib\contextlib.py", line 153, in __exit__
    self.gen.throw(typ, value, traceback)
  File "C:\Users\namst\AppData\Local\Programs\Python\Python310\lib\site-packages\httpcore\_exceptions.py", line 12, in map_exceptions
    raise to_exc(exc)
httpcore.ConnectTimeout: timed out

The above exception was the direct cause of the following exception:

Traceback (most recent call last):
  File "d:\pprojects\poe_beast_bot_v3\beast_bot\bot\bot_components\general\requests_controller\controller.py", line 52, in _execute_request
    response = client.request(
  File "C:\Users\namst\AppData\Local\Programs\Python\Python310\lib\site-packages\httpx\_client.py", line 815, in request
    return self.send(request, auth=auth, follow_redirects=follow_redirects)
  File "C:\Users\namst\AppData\Local\Programs\Python\Python310\lib\site-packages\httpx\_client.py", line 902, in send
    response = self._send_handling_auth(
  File "C:\Users\namst\AppData\Local\Programs\Python\Python310\lib\site-packages\httpx\_client.py", line 930, in _send_handling_auth
    response = self._send_handling_redirects(
  File "C:\Users\namst\AppData\Local\Programs\Python\Python310\lib\site-packages\httpx\_client.py", line 967, in _send_handling_redirects
    response = self._send_single_request(request)
  File "C:\Users\namst\AppData\Local\Programs\Python\Python310\lib\site-packages\httpx\_client.py", line 1003, in _send_single_request
    response = transport.handle_request(request)
  File "C:\Users\namst\AppData\Local\Programs\Python\Python310\lib\site-packages\httpx\_transports\default.py", line 217, in handle_request
    with map_httpcore_exceptions():
  File "C:\Users\namst\AppData\Local\Programs\Python\Python310\lib\contextlib.py", line 153, in __exit__
    self.gen.throw(typ, value, traceback)
  File "C:\Users\namst\AppData\Local\Programs\Python\Python310\lib\site-packages\httpx\_transports\default.py", line 77, in map_httpcore_exceptions
    raise mapped_exc(message) from exc
httpx.ConnectTimeout: timed out
